<?xml version="1.0" encoding="utf-8" standalone="yes"?>
<rss version="2.0" xmlns:atom="http://www.w3.org/2005/Atom">
  <channel>
    <title>Exception on The Python Corner</title>
    <link>https://mastro35.github.io/tpc/tags/exception/</link>
    <description>Recent content in Exception on The Python Corner</description>
    <generator>Hugo -- gohugo.io</generator>
    <language>en-us</language>
    <copyright>Davide Mastromatteo</copyright>
    <lastBuildDate>Tue, 10 Jan 2017 19:02:01 +0100</lastBuildDate><atom:link href="https://mastro35.github.io/tpc/tags/exception/index.xml" rel="self" type="application/rss+xml" />
    <item>
      <title>Working with Exception in Python</title>
      <link>https://mastro35.github.io/tpc/posts/2017-01-10-working-with-exception-in-python/</link>
      <pubDate>Tue, 10 Jan 2017 19:02:01 +0100</pubDate>
      
      <guid>https://mastro35.github.io/tpc/posts/2017-01-10-working-with-exception-in-python/</guid>
      <description>According to the official documentation, an exception is &amp;ldquo;an error detected during execution not unconditionally fatal&amp;rdquo;. Let&amp;rsquo;s start the interpreter and write:
1&amp;gt;&amp;gt;&amp;gt; 5/0 2Traceback (most recent call last): 3 File &amp;#34;&amp;lt;pyshell#7&amp;gt;&amp;#34;, line 1, in &amp;lt;module&amp;gt; 4 5/0 5ZeroDivisionError: division by zero As you can see we asked the interpreter to divide the number 5 by 0. Even if our request was syntactically correct when the interpreter tried to compute it, it &amp;ldquo;raised&amp;rdquo; the ZeroDivisionError exception to signal us that we asked something impossible.</description>
    </item>
    
  </channel>
</rss>
